/home/drew/pi/memeologia/venv/lib/python3.11/site-packages/pydantic/_internal/_config.py:341: UserWarning: Valid config keys have changed in V2:
* 'orm_mode' has been renamed to 'from_attributes'
  warnings.warn(message, UserWarning)
INFO:     Started server process [4484]
INFO:     Waiting for application startup.
INFO:     Application startup complete.
INFO:     Uvicorn running on http://0.0.0.0:8000 (Press CTRL+C to quit)
INFO:     Shutting down
INFO:     Waiting for application shutdown.
INFO:     Application shutdown complete.
INFO:     Finished server process [4484]
/home/drew/pi/memeologia/venv/lib/python3.11/site-packages/pydantic/_internal/_config.py:341: UserWarning: Valid config keys have changed in V2:
* 'orm_mode' has been renamed to 'from_attributes'
  warnings.warn(message, UserWarning)
INFO:     Started server process [4501]
INFO:     Waiting for application startup.
INFO:     Application startup complete.
ERROR:    [Errno 98] error while attempting to bind on address ('0.0.0.0', 8000): address already in use
INFO:     Waiting for application shutdown.
INFO:     Application shutdown complete.
/home/drew/pi/memeologia/venv/lib/python3.11/site-packages/pydantic/_internal/_config.py:341: UserWarning: Valid config keys have changed in V2:
* 'orm_mode' has been renamed to 'from_attributes'
  warnings.warn(message, UserWarning)
INFO:     Started server process [4519]
INFO:     Waiting for application startup.
INFO:     Application startup complete.
INFO:     Uvicorn running on http://0.0.0.0:8000 (Press CTRL+C to quit)
INFO:     200.104.72.42:57646 - "GET /docs HTTP/1.1" 200 OK
INFO:     200.104.72.42:57646 - "GET /openapi.json HTTP/1.1" 200 OK
INFO:     154.213.184.18:43278 - "CONNECT example.com%3A443 HTTP/1.1" 404 Not Found
INFO:     200.104.72.42:57740 - "GET /docs HTTP/1.1" 200 OK
INFO:     200.104.72.42:57740 - "GET /openapi.json HTTP/1.1" 200 OK
INFO:     200.104.72.42:57756 - "GET /memes?page=1&limit=20 HTTP/1.1" 404 Not Found
INFO:     200.104.72.42:64265 - "GET /memes?page=1&limit=20 HTTP/1.1" 404 Not Found
INFO:     200.104.72.42:64269 - "OPTIONS /usuarios HTTP/1.1" 200 OK
(trapped) error reading bcrypt version
Traceback (most recent call last):
  File "/home/drew/pi/memeologia/venv/lib/python3.11/site-packages/passlib/handlers/bcrypt.py", line 620, in _load_backend_mixin
    version = _bcrypt.__about__.__version__
              ^^^^^^^^^^^^^^^^^
AttributeError: module 'bcrypt' has no attribute '__about__'
INFO:     200.104.72.42:64269 - "POST /usuarios HTTP/1.1" 200 OK
INFO:     200.104.72.42:64269 - "GET /memes?page=1&limit=20 HTTP/1.1" 404 Not Found
INFO:     200.104.72.42:64274 - "GET /memes?page=1&limit=20 HTTP/1.1" 404 Not Found
INFO:     200.104.72.42:64276 - "GET /api/usuario/2 HTTP/1.1" 200 OK
INFO:     200.104.72.42:64276 - "GET /memes?page=1&limit=20 HTTP/1.1" 404 Not Found
INFO:     200.104.72.42:64279 - "GET /memes?page=1&limit=20 HTTP/1.1" 404 Not Found
INFO:     200.104.72.42:64288 - "GET /memes?page=1&limit=20 HTTP/1.1" 404 Not Found
Conectado a S3 en la regi√≥n sa-east-1
Subiendo archivo al bucket 'memeologia' con nombre 'dac72a14-e2cd-4c85-b3ef-ce896750b45a.jpeg'
Archivo subido exitosamente: https://memeologia.s3.sa-east-1.amazonaws.com/dac72a14-e2cd-4c85-b3ef-ce896750b45a.jpeg
INFO:     200.104.72.42:64290 - "POST /upload HTTP/1.1" 200 OK
INFO:     200.104.72.42:64290 - "GET /memes?page=1&limit=20 HTTP/1.1" 404 Not Found
INFO:     200.104.72.42:64293 - "GET /memes?page=1&limit=20 HTTP/1.1" 404 Not Found
INFO:     200.104.72.42:57817 - "GET /memes?page=1&limit=20 HTTP/1.1" 404 Not Found
INFO:     Shutting down
INFO:     Waiting for application shutdown.
INFO:     Application shutdown complete.
INFO:     Finished server process [4519]
/home/drew/pi/memeologia/venv/lib/python3.11/site-packages/pydantic/_internal/_config.py:341: UserWarning: Valid config keys have changed in V2:
* 'orm_mode' has been renamed to 'from_attributes'
  warnings.warn(message, UserWarning)
INFO:     Started server process [713]
INFO:     Waiting for application startup.
INFO:     Application startup complete.
INFO:     Uvicorn running on http://0.0.0.0:8000 (Press CTRL+C to quit)
INFO:     200.104.72.42:58411 - "GET /memes?page=1&limit=20 HTTP/1.1" 404 Not Found
INFO:     200.104.72.42:58499 - "GET /memes?page=1&limit=20 HTTP/1.1" 404 Not Found
INFO:     200.104.72.42:58501 - "GET /memes?page=1&limit=20 HTTP/1.1" 404 Not Found
INFO:     200.104.72.42:58540 - "GET /memes?page=1&limit=20 HTTP/1.1" 404 Not Found
INFO:     200.104.72.42:58551 - "GET /memes?page=1&limit=20 HTTP/1.1" 404 Not Found
INFO:     200.104.72.42:58551 - "GET /memes?page=1&limit=20 HTTP/1.1" 404 Not Found
INFO:     200.104.72.42:58551 - "GET /memes?page=1&limit=20 HTTP/1.1" 404 Not Found
INFO:     200.104.72.42:58552 - "GET /memes?page=1&limit=20 HTTP/1.1" 404 Not Found
INFO:     200.104.72.42:58552 - "GET /memes?page=1&limit=20 HTTP/1.1" 404 Not Found
INFO:     200.104.72.42:58552 - "GET /memes?page=1&limit=20 HTTP/1.1" 404 Not Found
INFO:     Shutting down
INFO:     Waiting for application shutdown.
INFO:     Application shutdown complete.
INFO:     Finished server process [713]
/home/drew/pi/memeologia/venv/lib/python3.11/site-packages/pydantic/_internal/_config.py:341: UserWarning: Valid config keys have changed in V2:
* 'orm_mode' has been renamed to 'from_attributes'
  warnings.warn(message, UserWarning)
Traceback (most recent call last):
  File "/home/drew/pi/memeologia/venv/lib/python3.11/site-packages/sqlalchemy/engine/base.py", line 146, in __init__
    self._dbapi_connection = engine.raw_connection()
                             ^^^^^^^^^^^^^^^^^^^^^^^
  File "/home/drew/pi/memeologia/venv/lib/python3.11/site-packages/sqlalchemy/engine/base.py", line 3302, in raw_connection
    return self.pool.connect()
           ^^^^^^^^^^^^^^^^^^^
  File "/home/drew/pi/memeologia/venv/lib/python3.11/site-packages/sqlalchemy/pool/base.py", line 449, in connect
    return _ConnectionFairy._checkout(self)
           ^^^^^^^^^^^^^^^^^^^^^^^^^^^^^^^^
  File "/home/drew/pi/memeologia/venv/lib/python3.11/site-packages/sqlalchemy/pool/base.py", line 1263, in _checkout
    fairy = _ConnectionRecord.checkout(pool)
            ^^^^^^^^^^^^^^^^^^^^^^^^^^^^^^^^
  File "/home/drew/pi/memeologia/venv/lib/python3.11/site-packages/sqlalchemy/pool/base.py", line 712, in checkout
    rec = pool._do_get()
          ^^^^^^^^^^^^^^
  File "/home/drew/pi/memeologia/venv/lib/python3.11/site-packages/sqlalchemy/pool/impl.py", line 179, in _do_get
    with util.safe_reraise():
  File "/home/drew/pi/memeologia/venv/lib/python3.11/site-packages/sqlalchemy/util/langhelpers.py", line 146, in __exit__
    raise exc_value.with_traceback(exc_tb)
  File "/home/drew/pi/memeologia/venv/lib/python3.11/site-packages/sqlalchemy/pool/impl.py", line 177, in _do_get
    return self._create_connection()
           ^^^^^^^^^^^^^^^^^^^^^^^^^
  File "/home/drew/pi/memeologia/venv/lib/python3.11/site-packages/sqlalchemy/pool/base.py", line 390, in _create_connection
    return _ConnectionRecord(self)
           ^^^^^^^^^^^^^^^^^^^^^^^
  File "/home/drew/pi/memeologia/venv/lib/python3.11/site-packages/sqlalchemy/pool/base.py", line 674, in __init__
    self.__connect()
  File "/home/drew/pi/memeologia/venv/lib/python3.11/site-packages/sqlalchemy/pool/base.py", line 900, in __connect
    with util.safe_reraise():
  File "/home/drew/pi/memeologia/venv/lib/python3.11/site-packages/sqlalchemy/util/langhelpers.py", line 146, in __exit__
    raise exc_value.with_traceback(exc_tb)
  File "/home/drew/pi/memeologia/venv/lib/python3.11/site-packages/sqlalchemy/pool/base.py", line 896, in __connect
    self.dbapi_connection = connection = pool._invoke_creator(self)
                                         ^^^^^^^^^^^^^^^^^^^^^^^^^^
  File "/home/drew/pi/memeologia/venv/lib/python3.11/site-packages/sqlalchemy/engine/create.py", line 643, in connect
    return dialect.connect(*cargs, **cparams)
           ^^^^^^^^^^^^^^^^^^^^^^^^^^^^^^^^^^
  File "/home/drew/pi/memeologia/venv/lib/python3.11/site-packages/sqlalchemy/engine/default.py", line 621, in connect
    return self.loaded_dbapi.connect(*cargs, **cparams)
           ^^^^^^^^^^^^^^^^^^^^^^^^^^^^^^^^^^^^^^^^^^^^
  File "/home/drew/pi/memeologia/venv/lib/python3.11/site-packages/pymysql/connections.py", line 361, in __init__
    self.connect()
  File "/home/drew/pi/memeologia/venv/lib/python3.11/site-packages/pymysql/connections.py", line 669, in connect
    self._request_authentication()
  File "/home/drew/pi/memeologia/venv/lib/python3.11/site-packages/pymysql/connections.py", line 957, in _request_authentication
    auth_packet = self._read_packet()
                  ^^^^^^^^^^^^^^^^^^^
  File "/home/drew/pi/memeologia/venv/lib/python3.11/site-packages/pymysql/connections.py", line 775, in _read_packet
    packet.raise_for_error()
  File "/home/drew/pi/memeologia/venv/lib/python3.11/site-packages/pymysql/protocol.py", line 219, in raise_for_error
    err.raise_mysql_exception(self._data)
  File "/home/drew/pi/memeologia/venv/lib/python3.11/site-packages/pymysql/err.py", line 150, in raise_mysql_exception
    raise errorclass(errno, errval)
pymysql.err.OperationalError: (1049, "Unknown database 'memeologia_bd'")

The above exception was the direct cause of the following exception:

Traceback (most recent call last):
  File "/home/drew/pi/memeologia/venv/bin/uvicorn", line 8, in <module>
    sys.exit(main())
             ^^^^^^
  File "/home/drew/pi/memeologia/venv/lib/python3.11/site-packages/click/core.py", line 1157, in __call__
    return self.main(*args, **kwargs)
           ^^^^^^^^^^^^^^^^^^^^^^^^^^
  File "/home/drew/pi/memeologia/venv/lib/python3.11/site-packages/click/core.py", line 1078, in main
    rv = self.invoke(ctx)
         ^^^^^^^^^^^^^^^^
  File "/home/drew/pi/memeologia/venv/lib/python3.11/site-packages/click/core.py", line 1434, in invoke
    return ctx.invoke(self.callback, **ctx.params)
           ^^^^^^^^^^^^^^^^^^^^^^^^^^^^^^^^^^^^^^^
  File "/home/drew/pi/memeologia/venv/lib/python3.11/site-packages/click/core.py", line 783, in invoke
    return __callback(*args, **kwargs)
           ^^^^^^^^^^^^^^^^^^^^^^^^^^^
  File "/home/drew/pi/memeologia/venv/lib/python3.11/site-packages/uvicorn/main.py", line 412, in main
    run(
  File "/home/drew/pi/memeologia/venv/lib/python3.11/site-packages/uvicorn/main.py", line 579, in run
    server.run()
  File "/home/drew/pi/memeologia/venv/lib/python3.11/site-packages/uvicorn/server.py", line 65, in run
    return asyncio.run(self.serve(sockets=sockets))
           ^^^^^^^^^^^^^^^^^^^^^^^^^^^^^^^^^^^^^^^^
  File "/usr/lib/python3.11/asyncio/runners.py", line 190, in run
    return runner.run(main)
           ^^^^^^^^^^^^^^^^
  File "/usr/lib/python3.11/asyncio/runners.py", line 118, in run
    return self._loop.run_until_complete(task)
           ^^^^^^^^^^^^^^^^^^^^^^^^^^^^^^^^^^^
  File "/usr/lib/python3.11/asyncio/base_events.py", line 653, in run_until_complete
    return future.result()
           ^^^^^^^^^^^^^^^
  File "/home/drew/pi/memeologia/venv/lib/python3.11/site-packages/uvicorn/server.py", line 69, in serve
    await self._serve(sockets)
  File "/home/drew/pi/memeologia/venv/lib/python3.11/site-packages/uvicorn/server.py", line 76, in _serve
    config.load()
  File "/home/drew/pi/memeologia/venv/lib/python3.11/site-packages/uvicorn/config.py", line 434, in load
    self.loaded_app = import_from_string(self.app)
                      ^^^^^^^^^^^^^^^^^^^^^^^^^^^^
  File "/home/drew/pi/memeologia/venv/lib/python3.11/site-packages/uvicorn/importer.py", line 19, in import_from_string
    module = importlib.import_module(module_str)
             ^^^^^^^^^^^^^^^^^^^^^^^^^^^^^^^^^^^
  File "/usr/lib/python3.11/importlib/__init__.py", line 126, in import_module
    return _bootstrap._gcd_import(name[level:], package, level)
           ^^^^^^^^^^^^^^^^^^^^^^^^^^^^^^^^^^^^^^^^^^^^^^^^^^^^
  File "<frozen importlib._bootstrap>", line 1206, in _gcd_import
  File "<frozen importlib._bootstrap>", line 1178, in _find_and_load
  File "<frozen importlib._bootstrap>", line 1149, in _find_and_load_unlocked
  File "<frozen importlib._bootstrap>", line 690, in _load_unlocked
  File "<frozen importlib._bootstrap_external>", line 940, in exec_module
  File "<frozen importlib._bootstrap>", line 241, in _call_with_frames_removed
  File "/home/drew/pi/memeologia/memeologia_back/main.py", line 10, in <module>
    models_sql.Base.metadata.create_all(bind=engine)
  File "/home/drew/pi/memeologia/venv/lib/python3.11/site-packages/sqlalchemy/sql/schema.py", line 5868, in create_all
    bind._run_ddl_visitor(
  File "/home/drew/pi/memeologia/venv/lib/python3.11/site-packages/sqlalchemy/engine/base.py", line 3252, in _run_ddl_visitor
    with self.begin() as conn:
  File "/usr/lib/python3.11/contextlib.py", line 137, in __enter__
    return next(self.gen)
           ^^^^^^^^^^^^^^
  File "/home/drew/pi/memeologia/venv/lib/python3.11/site-packages/sqlalchemy/engine/base.py", line 3242, in begin
    with self.connect() as conn:
         ^^^^^^^^^^^^^^
  File "/home/drew/pi/memeologia/venv/lib/python3.11/site-packages/sqlalchemy/engine/base.py", line 3278, in connect
    return self._connection_cls(self)
           ^^^^^^^^^^^^^^^^^^^^^^^^^^
  File "/home/drew/pi/memeologia/venv/lib/python3.11/site-packages/sqlalchemy/engine/base.py", line 148, in __init__
    Connection._handle_dbapi_exception_noconnection(
  File "/home/drew/pi/memeologia/venv/lib/python3.11/site-packages/sqlalchemy/engine/base.py", line 2442, in _handle_dbapi_exception_noconnection
    raise sqlalchemy_exception.with_traceback(exc_info[2]) from e
  File "/home/drew/pi/memeologia/venv/lib/python3.11/site-packages/sqlalchemy/engine/base.py", line 146, in __init__
    self._dbapi_connection = engine.raw_connection()
                             ^^^^^^^^^^^^^^^^^^^^^^^
  File "/home/drew/pi/memeologia/venv/lib/python3.11/site-packages/sqlalchemy/engine/base.py", line 3302, in raw_connection
    return self.pool.connect()
           ^^^^^^^^^^^^^^^^^^^
  File "/home/drew/pi/memeologia/venv/lib/python3.11/site-packages/sqlalchemy/pool/base.py", line 449, in connect
    return _ConnectionFairy._checkout(self)
           ^^^^^^^^^^^^^^^^^^^^^^^^^^^^^^^^
  File "/home/drew/pi/memeologia/venv/lib/python3.11/site-packages/sqlalchemy/pool/base.py", line 1263, in _checkout
    fairy = _ConnectionRecord.checkout(pool)
            ^^^^^^^^^^^^^^^^^^^^^^^^^^^^^^^^
  File "/home/drew/pi/memeologia/venv/lib/python3.11/site-packages/sqlalchemy/pool/base.py", line 712, in checkout
    rec = pool._do_get()
          ^^^^^^^^^^^^^^
  File "/home/drew/pi/memeologia/venv/lib/python3.11/site-packages/sqlalchemy/pool/impl.py", line 179, in _do_get
    with util.safe_reraise():
  File "/home/drew/pi/memeologia/venv/lib/python3.11/site-packages/sqlalchemy/util/langhelpers.py", line 146, in __exit__
    raise exc_value.with_traceback(exc_tb)
  File "/home/drew/pi/memeologia/venv/lib/python3.11/site-packages/sqlalchemy/pool/impl.py", line 177, in _do_get
    return self._create_connection()
           ^^^^^^^^^^^^^^^^^^^^^^^^^
  File "/home/drew/pi/memeologia/venv/lib/python3.11/site-packages/sqlalchemy/pool/base.py", line 390, in _create_connection
    return _ConnectionRecord(self)
           ^^^^^^^^^^^^^^^^^^^^^^^
  File "/home/drew/pi/memeologia/venv/lib/python3.11/site-packages/sqlalchemy/pool/base.py", line 674, in __init__
    self.__connect()
  File "/home/drew/pi/memeologia/venv/lib/python3.11/site-packages/sqlalchemy/pool/base.py", line 900, in __connect
    with util.safe_reraise():
  File "/home/drew/pi/memeologia/venv/lib/python3.11/site-packages/sqlalchemy/util/langhelpers.py", line 146, in __exit__
    raise exc_value.with_traceback(exc_tb)
  File "/home/drew/pi/memeologia/venv/lib/python3.11/site-packages/sqlalchemy/pool/base.py", line 896, in __connect
    self.dbapi_connection = connection = pool._invoke_creator(self)
                                         ^^^^^^^^^^^^^^^^^^^^^^^^^^
  File "/home/drew/pi/memeologia/venv/lib/python3.11/site-packages/sqlalchemy/engine/create.py", line 643, in connect
    return dialect.connect(*cargs, **cparams)
           ^^^^^^^^^^^^^^^^^^^^^^^^^^^^^^^^^^
  File "/home/drew/pi/memeologia/venv/lib/python3.11/site-packages/sqlalchemy/engine/default.py", line 621, in connect
    return self.loaded_dbapi.connect(*cargs, **cparams)
           ^^^^^^^^^^^^^^^^^^^^^^^^^^^^^^^^^^^^^^^^^^^^
  File "/home/drew/pi/memeologia/venv/lib/python3.11/site-packages/pymysql/connections.py", line 361, in __init__
    self.connect()
  File "/home/drew/pi/memeologia/venv/lib/python3.11/site-packages/pymysql/connections.py", line 669, in connect
    self._request_authentication()
  File "/home/drew/pi/memeologia/venv/lib/python3.11/site-packages/pymysql/connections.py", line 957, in _request_authentication
    auth_packet = self._read_packet()
                  ^^^^^^^^^^^^^^^^^^^
  File "/home/drew/pi/memeologia/venv/lib/python3.11/site-packages/pymysql/connections.py", line 775, in _read_packet
    packet.raise_for_error()
  File "/home/drew/pi/memeologia/venv/lib/python3.11/site-packages/pymysql/protocol.py", line 219, in raise_for_error
    err.raise_mysql_exception(self._data)
  File "/home/drew/pi/memeologia/venv/lib/python3.11/site-packages/pymysql/err.py", line 150, in raise_mysql_exception
    raise errorclass(errno, errval)
sqlalchemy.exc.OperationalError: (pymysql.err.OperationalError) (1049, "Unknown database 'memeologia_bd'")
(Background on this error at: https://sqlalche.me/e/20/e3q8)
/home/drew/pi/memeologia/venv/lib/python3.11/site-packages/pydantic/_internal/_config.py:341: UserWarning: Valid config keys have changed in V2:
* 'orm_mode' has been renamed to 'from_attributes'
  warnings.warn(message, UserWarning)
Traceback (most recent call last):
  File "/home/drew/pi/memeologia/venv/lib/python3.11/site-packages/sqlalchemy/engine/base.py", line 146, in __init__
    self._dbapi_connection = engine.raw_connection()
                             ^^^^^^^^^^^^^^^^^^^^^^^
  File "/home/drew/pi/memeologia/venv/lib/python3.11/site-packages/sqlalchemy/engine/base.py", line 3302, in raw_connection
    return self.pool.connect()
           ^^^^^^^^^^^^^^^^^^^
  File "/home/drew/pi/memeologia/venv/lib/python3.11/site-packages/sqlalchemy/pool/base.py", line 449, in connect
    return _ConnectionFairy._checkout(self)
           ^^^^^^^^^^^^^^^^^^^^^^^^^^^^^^^^
  File "/home/drew/pi/memeologia/venv/lib/python3.11/site-packages/sqlalchemy/pool/base.py", line 1263, in _checkout
    fairy = _ConnectionRecord.checkout(pool)
            ^^^^^^^^^^^^^^^^^^^^^^^^^^^^^^^^
  File "/home/drew/pi/memeologia/venv/lib/python3.11/site-packages/sqlalchemy/pool/base.py", line 712, in checkout
    rec = pool._do_get()
          ^^^^^^^^^^^^^^
  File "/home/drew/pi/memeologia/venv/lib/python3.11/site-packages/sqlalchemy/pool/impl.py", line 179, in _do_get
    with util.safe_reraise():
  File "/home/drew/pi/memeologia/venv/lib/python3.11/site-packages/sqlalchemy/util/langhelpers.py", line 146, in __exit__
    raise exc_value.with_traceback(exc_tb)
  File "/home/drew/pi/memeologia/venv/lib/python3.11/site-packages/sqlalchemy/pool/impl.py", line 177, in _do_get
    return self._create_connection()
           ^^^^^^^^^^^^^^^^^^^^^^^^^
  File "/home/drew/pi/memeologia/venv/lib/python3.11/site-packages/sqlalchemy/pool/base.py", line 390, in _create_connection
    return _ConnectionRecord(self)
           ^^^^^^^^^^^^^^^^^^^^^^^
  File "/home/drew/pi/memeologia/venv/lib/python3.11/site-packages/sqlalchemy/pool/base.py", line 674, in __init__
    self.__connect()
  File "/home/drew/pi/memeologia/venv/lib/python3.11/site-packages/sqlalchemy/pool/base.py", line 900, in __connect
    with util.safe_reraise():
  File "/home/drew/pi/memeologia/venv/lib/python3.11/site-packages/sqlalchemy/util/langhelpers.py", line 146, in __exit__
    raise exc_value.with_traceback(exc_tb)
  File "/home/drew/pi/memeologia/venv/lib/python3.11/site-packages/sqlalchemy/pool/base.py", line 896, in __connect
    self.dbapi_connection = connection = pool._invoke_creator(self)
                                         ^^^^^^^^^^^^^^^^^^^^^^^^^^
  File "/home/drew/pi/memeologia/venv/lib/python3.11/site-packages/sqlalchemy/engine/create.py", line 643, in connect
    return dialect.connect(*cargs, **cparams)
           ^^^^^^^^^^^^^^^^^^^^^^^^^^^^^^^^^^
  File "/home/drew/pi/memeologia/venv/lib/python3.11/site-packages/sqlalchemy/engine/default.py", line 621, in connect
    return self.loaded_dbapi.connect(*cargs, **cparams)
           ^^^^^^^^^^^^^^^^^^^^^^^^^^^^^^^^^^^^^^^^^^^^
  File "/home/drew/pi/memeologia/venv/lib/python3.11/site-packages/pymysql/connections.py", line 361, in __init__
    self.connect()
  File "/home/drew/pi/memeologia/venv/lib/python3.11/site-packages/pymysql/connections.py", line 669, in connect
    self._request_authentication()
  File "/home/drew/pi/memeologia/venv/lib/python3.11/site-packages/pymysql/connections.py", line 957, in _request_authentication
    auth_packet = self._read_packet()
                  ^^^^^^^^^^^^^^^^^^^
  File "/home/drew/pi/memeologia/venv/lib/python3.11/site-packages/pymysql/connections.py", line 775, in _read_packet
    packet.raise_for_error()
  File "/home/drew/pi/memeologia/venv/lib/python3.11/site-packages/pymysql/protocol.py", line 219, in raise_for_error
    err.raise_mysql_exception(self._data)
  File "/home/drew/pi/memeologia/venv/lib/python3.11/site-packages/pymysql/err.py", line 150, in raise_mysql_exception
    raise errorclass(errno, errval)
pymysql.err.OperationalError: (1049, "Unknown database 'memeologia_bd'")

The above exception was the direct cause of the following exception:

Traceback (most recent call last):
  File "/home/drew/pi/memeologia/venv/bin/uvicorn", line 8, in <module>
    sys.exit(main())
             ^^^^^^
  File "/home/drew/pi/memeologia/venv/lib/python3.11/site-packages/click/core.py", line 1157, in __call__
    return self.main(*args, **kwargs)
           ^^^^^^^^^^^^^^^^^^^^^^^^^^
  File "/home/drew/pi/memeologia/venv/lib/python3.11/site-packages/click/core.py", line 1078, in main
    rv = self.invoke(ctx)
         ^^^^^^^^^^^^^^^^
  File "/home/drew/pi/memeologia/venv/lib/python3.11/site-packages/click/core.py", line 1434, in invoke
    return ctx.invoke(self.callback, **ctx.params)
           ^^^^^^^^^^^^^^^^^^^^^^^^^^^^^^^^^^^^^^^
  File "/home/drew/pi/memeologia/venv/lib/python3.11/site-packages/click/core.py", line 783, in invoke
    return __callback(*args, **kwargs)
           ^^^^^^^^^^^^^^^^^^^^^^^^^^^
  File "/home/drew/pi/memeologia/venv/lib/python3.11/site-packages/uvicorn/main.py", line 412, in main
    run(
  File "/home/drew/pi/memeologia/venv/lib/python3.11/site-packages/uvicorn/main.py", line 579, in run
    server.run()
  File "/home/drew/pi/memeologia/venv/lib/python3.11/site-packages/uvicorn/server.py", line 65, in run
    return asyncio.run(self.serve(sockets=sockets))
           ^^^^^^^^^^^^^^^^^^^^^^^^^^^^^^^^^^^^^^^^
  File "/usr/lib/python3.11/asyncio/runners.py", line 190, in run
    return runner.run(main)
           ^^^^^^^^^^^^^^^^
  File "/usr/lib/python3.11/asyncio/runners.py", line 118, in run
    return self._loop.run_until_complete(task)
           ^^^^^^^^^^^^^^^^^^^^^^^^^^^^^^^^^^^
  File "/usr/lib/python3.11/asyncio/base_events.py", line 653, in run_until_complete
    return future.result()
           ^^^^^^^^^^^^^^^
  File "/home/drew/pi/memeologia/venv/lib/python3.11/site-packages/uvicorn/server.py", line 69, in serve
    await self._serve(sockets)
  File "/home/drew/pi/memeologia/venv/lib/python3.11/site-packages/uvicorn/server.py", line 76, in _serve
    config.load()
  File "/home/drew/pi/memeologia/venv/lib/python3.11/site-packages/uvicorn/config.py", line 434, in load
    self.loaded_app = import_from_string(self.app)
                      ^^^^^^^^^^^^^^^^^^^^^^^^^^^^
  File "/home/drew/pi/memeologia/venv/lib/python3.11/site-packages/uvicorn/importer.py", line 19, in import_from_string
    module = importlib.import_module(module_str)
             ^^^^^^^^^^^^^^^^^^^^^^^^^^^^^^^^^^^
  File "/usr/lib/python3.11/importlib/__init__.py", line 126, in import_module
    return _bootstrap._gcd_import(name[level:], package, level)
           ^^^^^^^^^^^^^^^^^^^^^^^^^^^^^^^^^^^^^^^^^^^^^^^^^^^^
  File "<frozen importlib._bootstrap>", line 1206, in _gcd_import
  File "<frozen importlib._bootstrap>", line 1178, in _find_and_load
  File "<frozen importlib._bootstrap>", line 1149, in _find_and_load_unlocked
  File "<frozen importlib._bootstrap>", line 690, in _load_unlocked
  File "<frozen importlib._bootstrap_external>", line 940, in exec_module
  File "<frozen importlib._bootstrap>", line 241, in _call_with_frames_removed
  File "/home/drew/pi/memeologia/memeologia_back/main.py", line 10, in <module>
    models_sql.Base.metadata.create_all(bind=engine)
  File "/home/drew/pi/memeologia/venv/lib/python3.11/site-packages/sqlalchemy/sql/schema.py", line 5868, in create_all
    bind._run_ddl_visitor(
  File "/home/drew/pi/memeologia/venv/lib/python3.11/site-packages/sqlalchemy/engine/base.py", line 3252, in _run_ddl_visitor
    with self.begin() as conn:
  File "/usr/lib/python3.11/contextlib.py", line 137, in __enter__
    return next(self.gen)
           ^^^^^^^^^^^^^^
  File "/home/drew/pi/memeologia/venv/lib/python3.11/site-packages/sqlalchemy/engine/base.py", line 3242, in begin
    with self.connect() as conn:
         ^^^^^^^^^^^^^^
  File "/home/drew/pi/memeologia/venv/lib/python3.11/site-packages/sqlalchemy/engine/base.py", line 3278, in connect
    return self._connection_cls(self)
           ^^^^^^^^^^^^^^^^^^^^^^^^^^
  File "/home/drew/pi/memeologia/venv/lib/python3.11/site-packages/sqlalchemy/engine/base.py", line 148, in __init__
    Connection._handle_dbapi_exception_noconnection(
  File "/home/drew/pi/memeologia/venv/lib/python3.11/site-packages/sqlalchemy/engine/base.py", line 2442, in _handle_dbapi_exception_noconnection
    raise sqlalchemy_exception.with_traceback(exc_info[2]) from e
  File "/home/drew/pi/memeologia/venv/lib/python3.11/site-packages/sqlalchemy/engine/base.py", line 146, in __init__
    self._dbapi_connection = engine.raw_connection()
                             ^^^^^^^^^^^^^^^^^^^^^^^
  File "/home/drew/pi/memeologia/venv/lib/python3.11/site-packages/sqlalchemy/engine/base.py", line 3302, in raw_connection
    return self.pool.connect()
           ^^^^^^^^^^^^^^^^^^^
  File "/home/drew/pi/memeologia/venv/lib/python3.11/site-packages/sqlalchemy/pool/base.py", line 449, in connect
    return _ConnectionFairy._checkout(self)
           ^^^^^^^^^^^^^^^^^^^^^^^^^^^^^^^^
  File "/home/drew/pi/memeologia/venv/lib/python3.11/site-packages/sqlalchemy/pool/base.py", line 1263, in _checkout
    fairy = _ConnectionRecord.checkout(pool)
            ^^^^^^^^^^^^^^^^^^^^^^^^^^^^^^^^
  File "/home/drew/pi/memeologia/venv/lib/python3.11/site-packages/sqlalchemy/pool/base.py", line 712, in checkout
    rec = pool._do_get()
          ^^^^^^^^^^^^^^
  File "/home/drew/pi/memeologia/venv/lib/python3.11/site-packages/sqlalchemy/pool/impl.py", line 179, in _do_get
    with util.safe_reraise():
  File "/home/drew/pi/memeologia/venv/lib/python3.11/site-packages/sqlalchemy/util/langhelpers.py", line 146, in __exit__
    raise exc_value.with_traceback(exc_tb)
  File "/home/drew/pi/memeologia/venv/lib/python3.11/site-packages/sqlalchemy/pool/impl.py", line 177, in _do_get
    return self._create_connection()
           ^^^^^^^^^^^^^^^^^^^^^^^^^
  File "/home/drew/pi/memeologia/venv/lib/python3.11/site-packages/sqlalchemy/pool/base.py", line 390, in _create_connection
    return _ConnectionRecord(self)
           ^^^^^^^^^^^^^^^^^^^^^^^
  File "/home/drew/pi/memeologia/venv/lib/python3.11/site-packages/sqlalchemy/pool/base.py", line 674, in __init__
    self.__connect()
  File "/home/drew/pi/memeologia/venv/lib/python3.11/site-packages/sqlalchemy/pool/base.py", line 900, in __connect
    with util.safe_reraise():
  File "/home/drew/pi/memeologia/venv/lib/python3.11/site-packages/sqlalchemy/util/langhelpers.py", line 146, in __exit__
    raise exc_value.with_traceback(exc_tb)
  File "/home/drew/pi/memeologia/venv/lib/python3.11/site-packages/sqlalchemy/pool/base.py", line 896, in __connect
    self.dbapi_connection = connection = pool._invoke_creator(self)
                                         ^^^^^^^^^^^^^^^^^^^^^^^^^^
  File "/home/drew/pi/memeologia/venv/lib/python3.11/site-packages/sqlalchemy/engine/create.py", line 643, in connect
    return dialect.connect(*cargs, **cparams)
           ^^^^^^^^^^^^^^^^^^^^^^^^^^^^^^^^^^
  File "/home/drew/pi/memeologia/venv/lib/python3.11/site-packages/sqlalchemy/engine/default.py", line 621, in connect
    return self.loaded_dbapi.connect(*cargs, **cparams)
           ^^^^^^^^^^^^^^^^^^^^^^^^^^^^^^^^^^^^^^^^^^^^
  File "/home/drew/pi/memeologia/venv/lib/python3.11/site-packages/pymysql/connections.py", line 361, in __init__
    self.connect()
  File "/home/drew/pi/memeologia/venv/lib/python3.11/site-packages/pymysql/connections.py", line 669, in connect
    self._request_authentication()
  File "/home/drew/pi/memeologia/venv/lib/python3.11/site-packages/pymysql/connections.py", line 957, in _request_authentication
    auth_packet = self._read_packet()
                  ^^^^^^^^^^^^^^^^^^^
  File "/home/drew/pi/memeologia/venv/lib/python3.11/site-packages/pymysql/connections.py", line 775, in _read_packet
    packet.raise_for_error()
  File "/home/drew/pi/memeologia/venv/lib/python3.11/site-packages/pymysql/protocol.py", line 219, in raise_for_error
    err.raise_mysql_exception(self._data)
  File "/home/drew/pi/memeologia/venv/lib/python3.11/site-packages/pymysql/err.py", line 150, in raise_mysql_exception
    raise errorclass(errno, errval)
sqlalchemy.exc.OperationalError: (pymysql.err.OperationalError) (1049, "Unknown database 'memeologia_bd'")
(Background on this error at: https://sqlalche.me/e/20/e3q8)
/home/drew/pi/memeologia/venv/lib/python3.11/site-packages/pydantic/_internal/_config.py:341: UserWarning: Valid config keys have changed in V2:
* 'orm_mode' has been renamed to 'from_attributes'
  warnings.warn(message, UserWarning)
Traceback (most recent call last):
  File "/home/drew/pi/memeologia/venv/lib/python3.11/site-packages/sqlalchemy/engine/base.py", line 146, in __init__
    self._dbapi_connection = engine.raw_connection()
                             ^^^^^^^^^^^^^^^^^^^^^^^
  File "/home/drew/pi/memeologia/venv/lib/python3.11/site-packages/sqlalchemy/engine/base.py", line 3302, in raw_connection
    return self.pool.connect()
           ^^^^^^^^^^^^^^^^^^^
  File "/home/drew/pi/memeologia/venv/lib/python3.11/site-packages/sqlalchemy/pool/base.py", line 449, in connect
    return _ConnectionFairy._checkout(self)
           ^^^^^^^^^^^^^^^^^^^^^^^^^^^^^^^^
  File "/home/drew/pi/memeologia/venv/lib/python3.11/site-packages/sqlalchemy/pool/base.py", line 1263, in _checkout
    fairy = _ConnectionRecord.checkout(pool)
            ^^^^^^^^^^^^^^^^^^^^^^^^^^^^^^^^
  File "/home/drew/pi/memeologia/venv/lib/python3.11/site-packages/sqlalchemy/pool/base.py", line 712, in checkout
    rec = pool._do_get()
          ^^^^^^^^^^^^^^
  File "/home/drew/pi/memeologia/venv/lib/python3.11/site-packages/sqlalchemy/pool/impl.py", line 179, in _do_get
    with util.safe_reraise():
  File "/home/drew/pi/memeologia/venv/lib/python3.11/site-packages/sqlalchemy/util/langhelpers.py", line 146, in __exit__
    raise exc_value.with_traceback(exc_tb)
  File "/home/drew/pi/memeologia/venv/lib/python3.11/site-packages/sqlalchemy/pool/impl.py", line 177, in _do_get
    return self._create_connection()
           ^^^^^^^^^^^^^^^^^^^^^^^^^
  File "/home/drew/pi/memeologia/venv/lib/python3.11/site-packages/sqlalchemy/pool/base.py", line 390, in _create_connection
    return _ConnectionRecord(self)
           ^^^^^^^^^^^^^^^^^^^^^^^
  File "/home/drew/pi/memeologia/venv/lib/python3.11/site-packages/sqlalchemy/pool/base.py", line 674, in __init__
    self.__connect()
  File "/home/drew/pi/memeologia/venv/lib/python3.11/site-packages/sqlalchemy/pool/base.py", line 900, in __connect
    with util.safe_reraise():
  File "/home/drew/pi/memeologia/venv/lib/python3.11/site-packages/sqlalchemy/util/langhelpers.py", line 146, in __exit__
    raise exc_value.with_traceback(exc_tb)
  File "/home/drew/pi/memeologia/venv/lib/python3.11/site-packages/sqlalchemy/pool/base.py", line 896, in __connect
    self.dbapi_connection = connection = pool._invoke_creator(self)
                                         ^^^^^^^^^^^^^^^^^^^^^^^^^^
  File "/home/drew/pi/memeologia/venv/lib/python3.11/site-packages/sqlalchemy/engine/create.py", line 643, in connect
    return dialect.connect(*cargs, **cparams)
           ^^^^^^^^^^^^^^^^^^^^^^^^^^^^^^^^^^
  File "/home/drew/pi/memeologia/venv/lib/python3.11/site-packages/sqlalchemy/engine/default.py", line 621, in connect
    return self.loaded_dbapi.connect(*cargs, **cparams)
           ^^^^^^^^^^^^^^^^^^^^^^^^^^^^^^^^^^^^^^^^^^^^
  File "/home/drew/pi/memeologia/venv/lib/python3.11/site-packages/pymysql/connections.py", line 361, in __init__
    self.connect()
  File "/home/drew/pi/memeologia/venv/lib/python3.11/site-packages/pymysql/connections.py", line 669, in connect
    self._request_authentication()
  File "/home/drew/pi/memeologia/venv/lib/python3.11/site-packages/pymysql/connections.py", line 957, in _request_authentication
    auth_packet = self._read_packet()
                  ^^^^^^^^^^^^^^^^^^^
  File "/home/drew/pi/memeologia/venv/lib/python3.11/site-packages/pymysql/connections.py", line 775, in _read_packet
    packet.raise_for_error()
  File "/home/drew/pi/memeologia/venv/lib/python3.11/site-packages/pymysql/protocol.py", line 219, in raise_for_error
    err.raise_mysql_exception(self._data)
  File "/home/drew/pi/memeologia/venv/lib/python3.11/site-packages/pymysql/err.py", line 150, in raise_mysql_exception
    raise errorclass(errno, errval)
pymysql.err.OperationalError: (1049, "Unknown database 'memeologia_bd'")

The above exception was the direct cause of the following exception:

Traceback (most recent call last):
  File "/home/drew/pi/memeologia/venv/bin/uvicorn", line 8, in <module>
    sys.exit(main())
             ^^^^^^
  File "/home/drew/pi/memeologia/venv/lib/python3.11/site-packages/click/core.py", line 1157, in __call__
    return self.main(*args, **kwargs)
           ^^^^^^^^^^^^^^^^^^^^^^^^^^
  File "/home/drew/pi/memeologia/venv/lib/python3.11/site-packages/click/core.py", line 1078, in main
    rv = self.invoke(ctx)
         ^^^^^^^^^^^^^^^^
  File "/home/drew/pi/memeologia/venv/lib/python3.11/site-packages/click/core.py", line 1434, in invoke
    return ctx.invoke(self.callback, **ctx.params)
           ^^^^^^^^^^^^^^^^^^^^^^^^^^^^^^^^^^^^^^^
  File "/home/drew/pi/memeologia/venv/lib/python3.11/site-packages/click/core.py", line 783, in invoke
    return __callback(*args, **kwargs)
           ^^^^^^^^^^^^^^^^^^^^^^^^^^^
  File "/home/drew/pi/memeologia/venv/lib/python3.11/site-packages/uvicorn/main.py", line 412, in main
    run(
  File "/home/drew/pi/memeologia/venv/lib/python3.11/site-packages/uvicorn/main.py", line 579, in run
    server.run()
  File "/home/drew/pi/memeologia/venv/lib/python3.11/site-packages/uvicorn/server.py", line 65, in run
    return asyncio.run(self.serve(sockets=sockets))
           ^^^^^^^^^^^^^^^^^^^^^^^^^^^^^^^^^^^^^^^^
  File "/usr/lib/python3.11/asyncio/runners.py", line 190, in run
    return runner.run(main)
           ^^^^^^^^^^^^^^^^
  File "/usr/lib/python3.11/asyncio/runners.py", line 118, in run
    return self._loop.run_until_complete(task)
           ^^^^^^^^^^^^^^^^^^^^^^^^^^^^^^^^^^^
  File "/usr/lib/python3.11/asyncio/base_events.py", line 653, in run_until_complete
    return future.result()
           ^^^^^^^^^^^^^^^
  File "/home/drew/pi/memeologia/venv/lib/python3.11/site-packages/uvicorn/server.py", line 69, in serve
    await self._serve(sockets)
  File "/home/drew/pi/memeologia/venv/lib/python3.11/site-packages/uvicorn/server.py", line 76, in _serve
    config.load()
  File "/home/drew/pi/memeologia/venv/lib/python3.11/site-packages/uvicorn/config.py", line 434, in load
    self.loaded_app = import_from_string(self.app)
                      ^^^^^^^^^^^^^^^^^^^^^^^^^^^^
  File "/home/drew/pi/memeologia/venv/lib/python3.11/site-packages/uvicorn/importer.py", line 19, in import_from_string
    module = importlib.import_module(module_str)
             ^^^^^^^^^^^^^^^^^^^^^^^^^^^^^^^^^^^
  File "/usr/lib/python3.11/importlib/__init__.py", line 126, in import_module
    return _bootstrap._gcd_import(name[level:], package, level)
           ^^^^^^^^^^^^^^^^^^^^^^^^^^^^^^^^^^^^^^^^^^^^^^^^^^^^
  File "<frozen importlib._bootstrap>", line 1206, in _gcd_import
  File "<frozen importlib._bootstrap>", line 1178, in _find_and_load
  File "<frozen importlib._bootstrap>", line 1149, in _find_and_load_unlocked
  File "<frozen importlib._bootstrap>", line 690, in _load_unlocked
  File "<frozen importlib._bootstrap_external>", line 940, in exec_module
  File "<frozen importlib._bootstrap>", line 241, in _call_with_frames_removed
  File "/home/drew/pi/memeologia/memeologia_back/main.py", line 10, in <module>
    models_sql.Base.metadata.create_all(bind=engine)
  File "/home/drew/pi/memeologia/venv/lib/python3.11/site-packages/sqlalchemy/sql/schema.py", line 5868, in create_all
    bind._run_ddl_visitor(
  File "/home/drew/pi/memeologia/venv/lib/python3.11/site-packages/sqlalchemy/engine/base.py", line 3252, in _run_ddl_visitor
    with self.begin() as conn:
  File "/usr/lib/python3.11/contextlib.py", line 137, in __enter__
    return next(self.gen)
           ^^^^^^^^^^^^^^
  File "/home/drew/pi/memeologia/venv/lib/python3.11/site-packages/sqlalchemy/engine/base.py", line 3242, in begin
    with self.connect() as conn:
         ^^^^^^^^^^^^^^
  File "/home/drew/pi/memeologia/venv/lib/python3.11/site-packages/sqlalchemy/engine/base.py", line 3278, in connect
    return self._connection_cls(self)
           ^^^^^^^^^^^^^^^^^^^^^^^^^^
  File "/home/drew/pi/memeologia/venv/lib/python3.11/site-packages/sqlalchemy/engine/base.py", line 148, in __init__
    Connection._handle_dbapi_exception_noconnection(
  File "/home/drew/pi/memeologia/venv/lib/python3.11/site-packages/sqlalchemy/engine/base.py", line 2442, in _handle_dbapi_exception_noconnection
    raise sqlalchemy_exception.with_traceback(exc_info[2]) from e
  File "/home/drew/pi/memeologia/venv/lib/python3.11/site-packages/sqlalchemy/engine/base.py", line 146, in __init__
    self._dbapi_connection = engine.raw_connection()
                             ^^^^^^^^^^^^^^^^^^^^^^^
  File "/home/drew/pi/memeologia/venv/lib/python3.11/site-packages/sqlalchemy/engine/base.py", line 3302, in raw_connection
    return self.pool.connect()
           ^^^^^^^^^^^^^^^^^^^
  File "/home/drew/pi/memeologia/venv/lib/python3.11/site-packages/sqlalchemy/pool/base.py", line 449, in connect
    return _ConnectionFairy._checkout(self)
           ^^^^^^^^^^^^^^^^^^^^^^^^^^^^^^^^
  File "/home/drew/pi/memeologia/venv/lib/python3.11/site-packages/sqlalchemy/pool/base.py", line 1263, in _checkout
    fairy = _ConnectionRecord.checkout(pool)
            ^^^^^^^^^^^^^^^^^^^^^^^^^^^^^^^^
  File "/home/drew/pi/memeologia/venv/lib/python3.11/site-packages/sqlalchemy/pool/base.py", line 712, in checkout
    rec = pool._do_get()
          ^^^^^^^^^^^^^^
  File "/home/drew/pi/memeologia/venv/lib/python3.11/site-packages/sqlalchemy/pool/impl.py", line 179, in _do_get
    with util.safe_reraise():
  File "/home/drew/pi/memeologia/venv/lib/python3.11/site-packages/sqlalchemy/util/langhelpers.py", line 146, in __exit__
    raise exc_value.with_traceback(exc_tb)
  File "/home/drew/pi/memeologia/venv/lib/python3.11/site-packages/sqlalchemy/pool/impl.py", line 177, in _do_get
    return self._create_connection()
           ^^^^^^^^^^^^^^^^^^^^^^^^^
  File "/home/drew/pi/memeologia/venv/lib/python3.11/site-packages/sqlalchemy/pool/base.py", line 390, in _create_connection
    return _ConnectionRecord(self)
           ^^^^^^^^^^^^^^^^^^^^^^^
  File "/home/drew/pi/memeologia/venv/lib/python3.11/site-packages/sqlalchemy/pool/base.py", line 674, in __init__
    self.__connect()
  File "/home/drew/pi/memeologia/venv/lib/python3.11/site-packages/sqlalchemy/pool/base.py", line 900, in __connect
    with util.safe_reraise():
  File "/home/drew/pi/memeologia/venv/lib/python3.11/site-packages/sqlalchemy/util/langhelpers.py", line 146, in __exit__
    raise exc_value.with_traceback(exc_tb)
  File "/home/drew/pi/memeologia/venv/lib/python3.11/site-packages/sqlalchemy/pool/base.py", line 896, in __connect
    self.dbapi_connection = connection = pool._invoke_creator(self)
                                         ^^^^^^^^^^^^^^^^^^^^^^^^^^
  File "/home/drew/pi/memeologia/venv/lib/python3.11/site-packages/sqlalchemy/engine/create.py", line 643, in connect
    return dialect.connect(*cargs, **cparams)
           ^^^^^^^^^^^^^^^^^^^^^^^^^^^^^^^^^^
  File "/home/drew/pi/memeologia/venv/lib/python3.11/site-packages/sqlalchemy/engine/default.py", line 621, in connect
    return self.loaded_dbapi.connect(*cargs, **cparams)
           ^^^^^^^^^^^^^^^^^^^^^^^^^^^^^^^^^^^^^^^^^^^^
  File "/home/drew/pi/memeologia/venv/lib/python3.11/site-packages/pymysql/connections.py", line 361, in __init__
    self.connect()
  File "/home/drew/pi/memeologia/venv/lib/python3.11/site-packages/pymysql/connections.py", line 669, in connect
    self._request_authentication()
  File "/home/drew/pi/memeologia/venv/lib/python3.11/site-packages/pymysql/connections.py", line 957, in _request_authentication
    auth_packet = self._read_packet()
                  ^^^^^^^^^^^^^^^^^^^
  File "/home/drew/pi/memeologia/venv/lib/python3.11/site-packages/pymysql/connections.py", line 775, in _read_packet
    packet.raise_for_error()
  File "/home/drew/pi/memeologia/venv/lib/python3.11/site-packages/pymysql/protocol.py", line 219, in raise_for_error
    err.raise_mysql_exception(self._data)
  File "/home/drew/pi/memeologia/venv/lib/python3.11/site-packages/pymysql/err.py", line 150, in raise_mysql_exception
    raise errorclass(errno, errval)
sqlalchemy.exc.OperationalError: (pymysql.err.OperationalError) (1049, "Unknown database 'memeologia_bd'")
(Background on this error at: https://sqlalche.me/e/20/e3q8)
/home/drew/pi/memeologia/venv/lib/python3.11/site-packages/pydantic/_internal/_config.py:341: UserWarning: Valid config keys have changed in V2:
* 'orm_mode' has been renamed to 'from_attributes'
  warnings.warn(message, UserWarning)
INFO:     Started server process [1280]
INFO:     Waiting for application startup.
INFO:     Application startup complete.
INFO:     Uvicorn running on http://0.0.0.0:8000 (Press CTRL+C to quit)
INFO:     200.104.72.42:58799 - "OPTIONS /usuarios HTTP/1.1" 200 OK
(trapped) error reading bcrypt version
Traceback (most recent call last):
  File "/home/drew/pi/memeologia/venv/lib/python3.11/site-packages/passlib/handlers/bcrypt.py", line 620, in _load_backend_mixin
    version = _bcrypt.__about__.__version__
              ^^^^^^^^^^^^^^^^^
AttributeError: module 'bcrypt' has no attribute '__about__'
INFO:     200.104.72.42:58799 - "POST /usuarios HTTP/1.1" 200 OK
INFO:     200.104.72.42:58805 - "GET /memes?page=1&limit=20 HTTP/1.1" 200 OK
INFO:     200.104.72.42:58805 - "GET /memes?page=1&limit=20 HTTP/1.1" 200 OK
INFO:     200.104.72.42:58806 - "GET /api/usuario/1 HTTP/1.1" 200 OK
Conectado a S3 en la regi√≥n sa-east-1
Subiendo archivo al bucket 'memeologia' con nombre '1_profile_image.jpg'
Archivo subido exitosamente: https://memeologia.s3.sa-east-1.amazonaws.com/1_profile_image.jpg
<models.models_sql.Usuario object at 0x6e77b150>
INFO:     200.104.72.42:58811 - "POST /api/usuario/1/photo HTTP/1.1" 200 OK
INFO:     200.104.72.42:58811 - "GET /api/usuario/1 HTTP/1.1" 200 OK
Conectado a S3 en la regi√≥n sa-east-1
Subiendo archivo al bucket 'memeologia' con nombre 'cover2.jpeg'
Archivo subido exitosamente: https://memeologia.s3.sa-east-1.amazonaws.com/cover2.jpeg
INFO:     200.104.72.42:58822 - "POST /upload HTTP/1.1" 200 OK
INFO:     200.104.72.42:58822 - "GET /memes?page=1&limit=20 HTTP/1.1" 200 OK
INFO:     200.104.72.42:58822 - "GET /memes?page=1&limit=20 HTTP/1.1" 200 OK
INFO:     200.104.72.42:58825 - "OPTIONS /like-meme/675eb6178cf85e53212c67d3 HTTP/1.1" 200 OK
INFO:     200.104.72.42:58826 - "POST /like-meme/675eb6178cf85e53212c67d3 HTTP/1.1" 401 Unauthorized
INFO:     200.104.72.42:58856 - "GET /memes?page=1&limit=20 HTTP/1.1" 200 OK
INFO:     200.104.72.42:58946 - "GET /memes?page=1&limit=20 HTTP/1.1" 200 OK
INFO:     200.104.72.42:58976 - "GET /memes?page=1&limit=20 HTTP/1.1" 200 OK
INFO:     200.104.72.42:58978 - "GET /api/usuario/1 HTTP/1.1" 200 OK
INFO:     200.104.72.42:58983 - "GET /memes?page=1&limit=20 HTTP/1.1" 200 OK
INFO:     200.104.72.42:58983 - "GET /memes?page=1&limit=20 HTTP/1.1" 200 OK
INFO:     200.104.72.42:58984 - "GET /memes?page=1&limit=20 HTTP/1.1" 200 OK
INFO:     200.104.72.42:58984 - "GET /memes?page=1&limit=20 HTTP/1.1" 200 OK
/home/drew/pi/memeologia/venv/lib/python3.11/site-packages/pydantic/_internal/_config.py:341: UserWarning: Valid config keys have changed in V2:
* 'orm_mode' has been renamed to 'from_attributes'
  warnings.warn(message, UserWarning)
INFO:     Started server process [1102]
INFO:     Waiting for application startup.
INFO:     Application startup complete.
INFO:     Uvicorn running on http://0.0.0.0:8000 (Press CTRL+C to quit)
INFO:     185.191.126.248:52574 - "GET / HTTP/1.1" 404 Not Found
INFO:     Shutting down
INFO:     Waiting for application shutdown.
INFO:     Application shutdown complete.
INFO:     Finished server process [1102]
/home/drew/pi/memeologia/venv/lib/python3.11/site-packages/pydantic/_internal/_config.py:341: UserWarning: Valid config keys have changed in V2:
* 'orm_mode' has been renamed to 'from_attributes'
  warnings.warn(message, UserWarning)
INFO:     Started server process [1630]
INFO:     Waiting for application startup.
INFO:     Application startup complete.
INFO:     Uvicorn running on http://0.0.0.0:8000 (Press CTRL+C to quit)
INFO:     200.104.72.42:59750 - "GET /docs HTTP/1.1" 200 OK
INFO:     200.104.72.42:59750 - "GET /openapi.json HTTP/1.1" 200 OK
INFO:     127.0.0.1:53710 - "GET /memes?page=1 HTTP/1.1" 200 OK
INFO:     127.0.0.1:51896 - "GET /memes?page=1&limit=20 HTTP/1.1" 200 OK
INFO:     127.0.0.1:39246 - "GET /memes?page=1&limit=20 HTTP/1.1" 200 OK
INFO:     127.0.0.1:47058 - "GET /memes?page=1&limit=20 HTTP/1.1" 200 OK
INFO:     127.0.0.1:47060 - "GET /memes?page=1&limit=20 HTTP/1.1" 200 OK
INFO:     127.0.0.1:45270 - "POST /login HTTP/1.1" 401 Unauthorized
(trapped) error reading bcrypt version
Traceback (most recent call last):
  File "/home/drew/pi/memeologia/venv/lib/python3.11/site-packages/passlib/handlers/bcrypt.py", line 620, in _load_backend_mixin
    version = _bcrypt.__about__.__version__
              ^^^^^^^^^^^^^^^^^
AttributeError: module 'bcrypt' has no attribute '__about__'
Usuario: 1, Token: eyJhbGciOiJIUzI1NiIsInR5cCI6IkpXVCJ9.eyJ1c3VhcmlvX2lkIjoxLCJleHAiOjE3MzQyNjkxOTh9.LjD1vwQFOexY4t386w-WMDYW9U6psqOx3tH-o2ACoeA
INFO:     127.0.0.1:45494 - "POST /login HTTP/1.1" 200 OK
INFO:     127.0.0.1:56606 - "GET /memes?page=1&limit=20 HTTP/1.1" 200 OK
INFO:     127.0.0.1:56610 - "GET /memes?page=1&limit=20 HTTP/1.1" 200 OK
INFO:     127.0.0.1:40058 - "GET /api/usuario/1 HTTP/1.1" 200 OK
INFO:     127.0.0.1:36016 - "GET /memes?page=1&limit=20 HTTP/1.1" 200 OK
INFO:     127.0.0.1:36032 - "GET /memes?page=1&limit=20 HTTP/1.1" 200 OK
INFO:     127.0.0.1:34054 - "GET /api/usuario/1 HTTP/1.1" 200 OK
INFO:     127.0.0.1:52322 - "GET /memes?page=1&limit=20 HTTP/1.1" 200 OK
INFO:     127.0.0.1:52330 - "GET /memes?page=1&limit=20 HTTP/1.1" 200 OK
INFO:     127.0.0.1:37532 - "GET /memes?page=1&limit=20 HTTP/1.1" 200 OK
INFO:     127.0.0.1:33092 - "GET /memes?page=1&limit=20 HTTP/1.1" 200 OK
INFO:     127.0.0.1:37562 - "GET /memes?page=1&limit=20 HTTP/1.1" 200 OK
INFO:     127.0.0.1:37572 - "GET /memes?page=1&limit=20 HTTP/1.1" 200 OK
INFO:     127.0.0.1:37574 - "GET /memes?page=1&limit=20 HTTP/1.1" 200 OK
INFO:     127.0.0.1:60834 - "GET /memes?page=1&limit=20 HTTP/1.1" 200 OK
INFO:     127.0.0.1:60840 - "GET /memes?page=1&limit=20 HTTP/1.1" 200 OK
INFO:     127.0.0.1:57880 - "GET /memes?page=1&limit=20 HTTP/1.1" 200 OK
INFO:     127.0.0.1:53636 - "GET /memes?page=1&limit=20 HTTP/1.1" 200 OK
INFO:     127.0.0.1:59208 - "GET /memes?page=1&limit=20 HTTP/1.1" 200 OK
INFO:     127.0.0.1:59224 - "GET /memes?page=1&limit=20 HTTP/1.1" 200 OK
INFO:     184.105.139.116:59483 - "GET / HTTP/1.1" 404 Not Found
INFO:     184.105.139.112:9745 - "GET /favicon.ico HTTP/1.1" 404 Not Found
INFO:     127.0.0.1:51446 - "GET /memes?page=1&limit=20 HTTP/1.1" 200 OK
INFO:     184.105.139.100:37731 - "GET http%3A//api.ipify.org/?format=json HTTP/1.1" 404 Not Found
INFO:     127.0.0.1:51156 - "GET /memes?page=1&limit=20 HTTP/1.1" 200 OK
INFO:     127.0.0.1:51162 - "GET /memes?page=1&limit=20 HTTP/1.1" 200 OK
INFO:     127.0.0.1:57446 - "GET /memes?page=1&limit=20 HTTP/1.1" 200 OK
INFO:     127.0.0.1:57458 - "GET /memes?page=1&limit=20 HTTP/1.1" 200 OK
INFO:     184.105.139.88:56121 - "CONNECT www.shadowserver.org%3A443 HTTP/1.1" 404 Not Found
INFO:     127.0.0.1:54262 - "GET /memes?page=1&limit=20 HTTP/1.1" 200 OK
INFO:     127.0.0.1:59106 - "POST /login HTTP/1.1" 401 Unauthorized
INFO:     127.0.0.1:53054 - "POST /login HTTP/1.1" 401 Unauthorized
INFO:     127.0.0.1:37726 - "GET /memes?page=1&limit=20 HTTP/1.1" 200 OK
INFO:     127.0.0.1:40128 - "GET /memes?page=1&limit=20 HTTP/1.1" 200 OK
INFO:     127.0.0.1:49210 - "GET /memes?page=1&limit=20 HTTP/1.1" 200 OK
INFO:     127.0.0.1:59790 - "GET /memes?page=1&limit=20 HTTP/1.1" 200 OK
INFO:     127.0.0.1:59802 - "GET /memes?page=1&limit=20 HTTP/1.1" 200 OK
INFO:     127.0.0.1:59810 - "GET /memes?page=1&limit=20 HTTP/1.1" 200 OK
INFO:     127.0.0.1:52226 - "GET /memes?page=1&limit=20 HTTP/1.1" 200 OK
INFO:     127.0.0.1:52234 - "GET /memes?page=1&limit=20 HTTP/1.1" 200 OK
INFO:     127.0.0.1:52244 - "GET /memes?page=1&limit=20 HTTP/1.1" 200 OK
INFO:     205.210.31.54:61290 - "GET / HTTP/1.1" 404 Not Found
INFO:     127.0.0.1:38642 - "GET /memes?page=1&limit=20 HTTP/1.1" 200 OK
WARNING:  Invalid HTTP request received.
INFO:     127.0.0.1:42212 - "GET /memes?page=1&limit=20 HTTP/1.1" 200 OK
INFO:     127.0.0.1:51236 - "GET /memes?page=1&limit=20 HTTP/1.1" 200 OK
INFO:     154.213.184.18:47530 - "CONNECT example.com%3A443 HTTP/1.1" 404 Not Found
INFO:     127.0.0.1:45244 - "GET /memes?page=1&limit=20 HTTP/1.1" 200 OK
INFO:     127.0.0.1:44470 - "GET /memes?page=1&limit=20 HTTP/1.1" 200 OK
INFO:     127.0.0.1:57140 - "GET /memes?page=1&limit=20 HTTP/1.1" 200 OK
INFO:     127.0.0.1:54536 - "POST /usuarios HTTP/1.1" 200 OK
INFO:     127.0.0.1:54544 - "GET /memes?page=1&limit=20 HTTP/1.1" 200 OK
INFO:     127.0.0.1:54558 - "GET /memes?page=1&limit=20 HTTP/1.1" 200 OK
INFO:     127.0.0.1:33296 - "GET /memes?page=1&limit=20 HTTP/1.1" 200 OK
INFO:     127.0.0.1:34514 - "GET /memes?page=1&limit=20 HTTP/1.1" 200 OK
INFO:     127.0.0.1:42690 - "POST /login HTTP/1.1" 401 Unauthorized
INFO:     127.0.0.1:41806 - "POST /login HTTP/1.1" 401 Unauthorized
INFO:     127.0.0.1:38926 - "POST /login HTTP/1.1" 401 Unauthorized
INFO:     127.0.0.1:38932 - "POST /login HTTP/1.1" 401 Unauthorized
INFO:     127.0.0.1:48100 - "GET /memes?page=1&limit=20 HTTP/1.1" 200 OK
INFO:     127.0.0.1:48114 - "POST /usuarios HTTP/1.1" 200 OK
INFO:     127.0.0.1:41576 - "GET /memes?page=1&limit=20 HTTP/1.1" 200 OK
INFO:     127.0.0.1:41590 - "GET /memes?page=1&limit=20 HTTP/1.1" 200 OK
INFO:     127.0.0.1:33758 - "GET /api/usuario/2 HTTP/1.1" 200 OK
INFO:     127.0.0.1:58310 - "GET /api/usuario/3 HTTP/1.1" 200 OK
INFO:     127.0.0.1:51958 - "GET /memes?page=1&limit=20 HTTP/1.1" 200 OK
INFO:     127.0.0.1:46170 - "GET /memes?page=1&limit=20 HTTP/1.1" 200 OK
INFO:     127.0.0.1:46184 - "GET /memes?page=1&limit=20 HTTP/1.1" 200 OK
Usuario: 3, Token: eyJhbGciOiJIUzI1NiIsInR5cCI6IkpXVCJ9.eyJ1c3VhcmlvX2lkIjozLCJleHAiOjE3MzQyODc1MjZ9.psY1nSK6ut6luPYs853eFBvkaVMQSX4UPYRZ5fgy2BM
INFO:     127.0.0.1:51048 - "POST /login HTTP/1.1" 200 OK
INFO:     127.0.0.1:60278 - "GET /memes?page=1&limit=20 HTTP/1.1" 200 OK
INFO:     127.0.0.1:60282 - "GET /memes?page=1&limit=20 HTTP/1.1" 200 OK
INFO:     127.0.0.1:57520 - "GET /api/usuario/3 HTTP/1.1" 200 OK
INFO:     127.0.0.1:52620 - "GET /memes?page=1&limit=20 HTTP/1.1" 200 OK
INFO:     127.0.0.1:52636 - "GET /memes?page=1&limit=20 HTTP/1.1" 200 OK
INFO:     127.0.0.1:39310 - "POST /usuarios HTTP/1.1" 200 OK
INFO:     127.0.0.1:51792 - "GET /memes?page=1&limit=20 HTTP/1.1" 200 OK
INFO:     127.0.0.1:51794 - "GET /memes?page=1&limit=20 HTTP/1.1" 200 OK
INFO:     127.0.0.1:53604 - "GET /memes?page=1&limit=20 HTTP/1.1" 200 OK
INFO:     127.0.0.1:53616 - "GET /memes?page=1&limit=20 HTTP/1.1" 200 OK
